Workbook

Sheet Customers
A1: Customer ID | B1: Customer | C1: Segment | D1: Region | E1: Product | F1: Start date | G1: Churn date | H1: ARR (USD)
A2: C0001 | B2: Saffron Retail 1 | C2: SMB | D2: NA | E2: Core + Analytics | F2: 45828 | H2: 16900
A3: C0002 | B3: Ember Financial 2 | C3: SMB | D3: NA | E3: Core + Analytics | F3: 46133 | H3: 9800
A4: C0003 | B4: Beacon Systems 3 | C4: SMB | D4: NA | E4: Core + Analytics | F4: 46013 | H4: 11500
A5: C0004 | B5: Quarry Systems 4 | C5: SMB | D5: NA | E5: Core | F5: 45055 | H5: 16000
A6: C0005 | B6: Beacon Retail 5 | C6: SMB | D6: NA | E6: Core | F6: 45762 | H6: 10500
A7: C0006 | B7: Orchard Logistics 6 | C7: SMB | D7: NA | E7: Core | F7: 45100 | H7: 18000
A8: C0007 | B8: Juniper Mobility 7 | C8: SMB | D8: EMEA | E8: Core | F8: 44713 | H8: 25100
A9: C0008 | B9: Cinder Labs 8 | C9: SMB | D9: EMEA | E9: Core | F9: 45135 | H9: 19100
A10: C0009 | B10: Tidal Mobility 9 | C10: SMB | D10: EMEA | E10: Core + Analytics | F10: 45093 | H10: 18600
A11: C0010 | B11: Juniper Financial 10 | C11: SMB | D11: NA | E11: Core | F11: 45382 | H11: 20000
A12: C0011 | B12: Northwind Retail 11 | C12: SMB | D12: NA | E12: Core + Analytics | F12: 45129 | G12: 46178 | H12: 13000
A13: C0012 | B13: Bluefin Energy 12 | C13: SMB | D13: NA | E13: Core | F13: 45783 | H13: 26400
A14: C0013 | B14: Quarry Systems 13 | C14: SMB | D14: EMEA | E14: Core | F14: 44642 | H14: 8400
A15: C0014 | B15: Zenith Retail 14 | C15: SMB | D15: NA | E15: Core | F15: 45670 | H15: 28900
A16: C0015 | B16: Northwind Systems 15 | C16: SMB | D16: NA | E16: Core + Analytics | F16: 44762 | H16: 14300
A17: C0016 | B17: Juniper Mobility 16 | C17: SMB | D17: EMEA | E17: Core + Analytics | F17: 45146 | H17: 26200
A18: C0017 | B18: Granite Health 17 | C18: SMB | D18: NA | E18: Core | F18: 45103 | H18: 15700
A19: C0018 | B19: Quarry Mobility 18 | C19: SMB | D19: NA | E19: Core | F19: 45938 | H19: 25100
A20: C0019 | B20: Marlin Labs 19 | C20: SMB | D20: EMEA | E20: Core + Analytics | F20: 45613 | H20: 26200
A21: C0020 | B21: Willow Health 20 | C21: SMB | D21: NA | E21: Core | F21: 45482 | H21: 21800
A22: C0021 | B22: Lantern Labs 21 | C22: SMB | D22: NA | E22: Core + Analytics | F22: 45175 | H22: 17000
A23: C0022 | B23: Marlin Retail 22 | C23: SMB | D23: NA | E23: Core + Analytics | F23: 45847 | H23: 32000
A24: C0023 | B24: Vantage Mobility 23 | C24: SMB | D24: EMEA | E24: Core | F24: 45873 | H24: 16400
A25: C0024 | B25: Juniper Foods 24 | C25: SMB | D25: NA | E25: Core | F25: 45101 | H25: 14100
A26: C0025 | B26: Harbor Energy 25 | C26: SMB | D26: NA | E26: Core | F26: 45139 | G26: 46140 | H26: 22600
A27: C0026 | B27: Zenith Logistics 26 | C27: SMB | D27: NA | E27: Core + Analytics | F27: 44565 | H27: 17000
A28: C0027 | B28: Northwind Labs 27 | C28: SMB | D28: NA | E28: Core | F28: 44999 | H28: 8000
A29: C0028 | B29: Harbor Media 28 | C29: SMB | D29: NA | E29: Core | F29: 45484 | H29: 21100
A30: C0029 | B30: Bluefin Financial 29 | C30: SMB | D30: NA | E30: Core + Analytics | F30: 45260 | H30: 17400
A31: C0030 | B31: Saffron Health 30 | C31: SMB | D31: NA | E31: Core | F31: 45209 | H31: 30900
A32: C0031 | B32: Quarry Mobility 31 | C32: SMB | D32: NA | E32: Core | F32: 44969 | H32: 8100
A33: C0032 | B33: Vantage Energy 32 | C33: SMB | D33: NA | E33: Core | F33: 45547 | G33: 46145 | H33: 15400
A34: C0033 | B34: Northwind Labs 33 | C34: SMB | D34: NA | E34: Core | F34: 46170 | H34: 9600
A35: C0034 | B35: Marlin Logistics 34 | C35: SMB | D35: NA | E35: Core | F35: 44566 | G35: 46186 | H35: 21400
A36: C0035 | B36: Juniper Financial 35 | C36: SMB | D36: EMEA | E36: Core | F36: 45281 | H36: 29500
A37: C0036 | B37: Quarry Energy 36 | C37: SMB | D37: EMEA | E37: Core + Analytics | F37: 45183 | H37: 27800
A38: C0037 | B38: Marlin Labs 37 | C38: SMB | D38: NA | E38: Core | F38: 44672 | H38: 17300
A39: C0038 | B39: Kestrel Labs 38 | C39: SMB | D39: NA | E39: Core + Analytics | F39: 44626 | H39: 22000
A40: C0039 | B40: Zenith Logistics 39 | C40: SMB | D40: NA | E40: Core | F40: 45309 | H40: 30800
...

Sheet ARR Bridge
A1: Ardent Labs, Inc. ARR bridge FY2026 (USD)
A3: Month | B3: Beginning ARR | C3: New | D3: Expansion | E3: Contraction | F3: Churn | G3: Ending ARR | H3: Net new ARR
A4: 46023 | B4: 23314200 | C4: =SUMIFS(Customers!$H:$H,Customers!$F:$F,">="&A4,Customers!$F:$F,"<="&EOMONTH(A4,0)) -> 214200 | D4: 283000 | E4: -50000 | F4: =-SUMIFS(Customers!$H:$H,Customers!$G:$G,">="&A4,Customers!$G:$G,"<="&EOMONTH(A4,0)) -> -119800 | G4: =B4+C4+D4+E4+F4 -> 23641600 | H4: =G4-B4 -> 327400
A5: 46054 | B5: =G4 -> 23641600 | C5: =SUMIFS(Customers!$H:$H,Customers!$F:$F,">="&A5,Customers!$F:$F,"<="&EOMONTH(A5,0)) -> 941300 | D5: 269000 | E5: -106000 | F5: =-SUMIFS(Customers!$H:$H,Customers!$G:$G,">="&A5,Customers!$G:$G,"<="&EOMONTH(A5,0)) -> -159300 | G5: =B5+C5+D5+E5+F5 -> 24586600 | H5: =G5-B5 -> 945000
A6: 46082 | B6: =G5 -> 24586600 | C6: =SUMIFS(Customers!$H:$H,Customers!$F:$F,">="&A6,Customers!$F:$F,"<="&EOMONTH(A6,0)) -> 8200 | D6: 289000 | E6: -64000 | F6: =-SUMIFS(Customers!$H:$H,Customers!$G:$G,">="&A6,Customers!$G:$G,"<="&EOMONTH(A6,0)) -> -162200 | G6: =B6+C6+D6+E6+F6 -> 24657600 | H6: =G6-B6 -> 71000
A7: 46113 | B7: =G6 -> 24657600 | C7: =SUMIFS(Customers!$H:$H,Customers!$F:$F,">="&A7,Customers!$F:$F,"<="&EOMONTH(A7,0)) -> 1022700 | D7: 416000 | E7: -52000 | F7: =-SUMIFS(Customers!$H:$H,Customers!$G:$G,">="&A7,Customers!$G:$G,"<="&EOMONTH(A7,0)) -> -315400 | G7: =B7+C7+D7+E7+F7 -> 25728900 | H7: =G7-B7 -> 1071300
A8: 46143 | B8: =G7 -> 25728900 | C8: =SUMIFS(Customers!$H:$H,Customers!$F:$F,">="&A8,Customers!$F:$F,"<="&EOMONTH(A8,0)) -> 912600 | D8: 412000 | E8: -45000 | F8: =-SUMIFS(Customers!$H:$H,Customers!$G:$G,">="&A8,Customers!$G:$G,"<="&EOMONTH(A8,0)) -> -231000 | G8: =B8+C8+D8+E8+F8 -> 26777500 | H8: =G8-B8 -> 1048600
A9: 46174 | B9: =G8 -> 26777500 | C9: =SUMIFS(Customers!$H:$H,Customers!$F:$F,">="&A9,Customers!$F:$F,"<="&EOMONTH(A9,0)) -> 977600 | D9: 278000 | E9: -118000 | F9: =-SUMIFS(Customers!$H:$H,Customers!$G:$G,">="&A9,Customers!$G:$G,"<="&EOMONTH(A9,0)) -> -266900 | G9: =B9+C9+D9+E9+F9 -> 27648200 | H9: =G9-B9 -> 870700
A10: 46204 | B10: =G9 -> 27648200 | C10: =SUMIFS(Customers!$H:$H,Customers!$F:$F,">="&A10,Customers!$F:$F,"<="&EOMONTH(A10,0)) -> 235700 | D10: 258000 | E10: -103000 | F10: =-SUMIFS(Customers!$H:$H,Customers!$G:$G,">="&A10,Customers!$G:$G,"<="&EOMONTH(A10,0)) -> -784600 | G10: =B10+C10+D10+E10+F10 -> 27254300 | H10: =G10-B10 -> -393900
A11: 46235 | B11: =G10 -> 27254300 | C11: =SUMIFS(Customers!$H:$H,Customers!$F:$F,">="&A11,Customers!$F:$F,"<="&EOMONTH(A11,0)) -> 528500 | D11: 203000 | E11: -80000 | F11: =-SUMIFS(Customers!$H:$H,Customers!$G:$G,">="&A11,Customers!$G:$G,"<="&EOMONTH(A11,0)) -> -58800 | G11: =B11+C11+D11+E11+F11 -> 27847000 | H11: =G11-B11 -> 592700
A12: 46266 | B12: =G11 -> 27847000 | C12: =SUMIFS(Customers!$H:$H,Customers!$F:$F,">="&A12,Customers!$F:$F,"<="&EOMONTH(A12,0)) -> 0 | D12: 387000 | E12: -60000 | F12: =-SUMIFS(Customers!$H:$H,Customers!$G:$G,">="&A12,Customers!$G:$G,"<="&EOMONTH(A12,0)) -> -240600 | G12: =B12+C12+D12+E12+F12 -> 27933400 | H12: =G12-B12 -> 86400
A14: NRR (YTD, simplified) | B14: =(B4+SUM(D4:D12)+SUM(E4:E12)+SUM(F4:F12))/B4 -> 0.99049506

Sheet KPI Summary
A1: Ardent Labs, Inc. Q3 FY2026 board KPIs
A3: Metric | B3: Q3 FY26 | C3: Definition | D3: Source
A4: Ending ARR | B4: ='ARR Bridge'!G12 -> 27933400 | C4: Contracted annual recurring revenue at Sep 30 | D4: ARR Bridge
A5: Run-rate revenue (monthly) | B5: =B4/12 -> 2327783.3 | C5: Ending ARR / 12 | D5: Derived
A6: GAAP revenue, Q3 | B6: 13539752 | C6: Recognised revenue Jul to Sep, USD | D6: Pasted from BvA Summary (Jul to Sep actual) 2026-10-03
A7: COGS, Q3 | B7: 2528525 | C7: Hosting + services delivery | D7: Pasted from BvA Summary 2026-10-03
A8: Customer Success cost, Q3 | B8: 1075556 | C8: CS department opex, all accounts | D8: Pasted from GL export 2026-10-03
A9: Gross margin % (investor) | B9: =(B6-B7-B8)/B6 -> 0.73381484 | C9: (Revenue - COGS - Customer Success cost) / Revenue | D9: Derived; differs from FP&A BvA definition
A10: Net new ARR, Q3 | B10: =SUM('ARR Bridge'!H10:H12) -> 285200 | C10: Ending minus beginning ARR, Jul to Sep | D10: ARR Bridge
A11: NRR | B11: ='ARR Bridge'!B14 -> 0.99049506 | C11: Net revenue retention (see Definitions) | D11: ARR Bridge
A12: EBITDA, Q3 | B12: -1172865 | C12: Revenue - COGS - Opex | D12: Pasted from BvA Summary 2026-10-03
A13: EBITDA margin, Q3 | B13: =B12/B6 -> -0.086623817 | C13: EBITDA / GAAP revenue | D13: Derived
A14: ARR growth YoY | B14: =B4/B15-1 -> 0.53606819 | C14: Ending ARR vs Sep-25 ARR | D14: Derived
A15: Sep-25 ARR (prior year) | B15: 18185000 | C15: Per FY25 board pack | D15: Typed
A16: Rule of 40 | B16: =B14+B13 -> 0.44944437 | C16: ARR growth + EBITDA margin | D16: Derived
A17: Net burn, Q3 | B17: -1850000 | C17: Operating cash outflow | D17: Cash model (not in this pack)
A18: Burn multiple | B18: =-B17/B10 -> 6.486676 | C18: Net burn / net new ARR | D18: Derived
A21: ARR by segment (active customers)
A22: Segment | B22: ARR | C22: Customers | D22: Average ARR
A23: SMB | B23: =SUMIFS(Customers!$H:$H,Customers!$C:$C,A23,Customers!$G:$G,"") -> 1637900 | C23: =COUNTIFS(Customers!$C:$C,A23,Customers!$G:$G,"") -> 82 | D23: =IFERROR(B23/C23,0) -> 19974.39
A24: Mid-Market | B24: =SUMIFS(Customers!$H:$H,Customers!$C:$C,A24,Customers!$G:$G,"") -> 6978500 | C24: =COUNTIFS(Customers!$C:$C,A24,Customers!$G:$G,"") -> 67 | D24: =IFERROR(B24/C24,0) -> 104156.72
A25: Enterprise | B25: =SUMIFS(Customers!$H:$H,Customers!$C:$C,A25,Customers!$G:$G,"") -> 17200000 | C25: =COUNTIFS(Customers!$C:$C,A25,Customers!$G:$G,"") -> 29 | D25: =IFERROR(B25/C25,0) -> 593103.45
A26: Total | B26: =SUM(B23:B25) -> 25816400 | C26: =SUM(C23:C25) -> 178 | D26: =IFERROR(B26/C26,0) -> 145035.96
A29: Notes
A30: Gross margin here follows the investor convention (includes Customer Success cost). The FP&A BvA file excludes it. Reconcile before the board meeting.
A31: Run-rate revenue is ARR / 12 and will not tie to GAAP revenue in the BvA file.
A32: Segment ARR excludes churned customers (blank churn date) but ignores expansion since renewal; the bridge total is the governed ARR figure.

Sheet Cohorts
A1: Logo retention by start-quarter cohort (%)
A2: Pasted from Looker dashboard 'Retention v3' on 2026-09-30. Not calculated in this workbook.
A4: Cohort | B4: M0 | C4: M3 | D4: M6 | E4: M9 | F4: M12 | G4: M18 | H4: M24
A5: 2024-Q1 | B5: 1 | C5: 0.949 | D5: 0.917 | E5: 0.896 | F5: 0.835 | G5: 0.82 | H5: 0.768
A6: 2024-Q2 | B6: 1 | C6: 0.981 | D6: 0.971 | E6: 0.905 | F6: 0.885 | G6: 0.845 | H6: 0.827
A7: 2024-Q3 | B7: 1 | C7: 0.985 | D7: 0.929 | E7: 0.899 | F7: 0.882 | G7: 0.864 | H7: 0.812
A8: 2024-Q4 | B8: 1 | C8: 0.968 | D8: 0.93 | E8: 0.916 | F8: 0.871 | G8: 0.821
A9: 2025-Q1 | B9: 1 | C9: 0.959 | D9: 0.911 | E9: 0.853 | F9: 0.834
A10: 2025-Q2 | B10: 1 | C10: 0.975 | D10: 0.964 | E10: 0.902
A11: 2025-Q3 | B11: 1 | C11: 0.971 | D11: 0.922
A12: 2025-Q4 | B12: 1 | C12: 0.976
A13: 2026-Q1 | B13: 1
A14: 2026-Q2

Sheet Definitions
A1: Metric | B1: Definition | C1: Owner | D1: Last reviewed | E1: Known differences
A2: ARR | B2: Sum of contracted annual recurring revenue for active customers, plus expansion since renewal per the billing system. | C2: RevOps | D2: 46295 | E2: Customers tab excludes post-renewal expansion; ARR Bridge includes it.
A3: Revenue (board pack) | B3: ARR / 12, run-rate. | C3: FP&A | D3: 46204 | E3: BvA file uses GAAP recognised revenue from the GL.
A4: Gross margin (investor) | B4: (Revenue - COGS - Customer Success cost) / Revenue. | C4: CFO | D4: 46204 | E4: FP&A BvA gross margin = (Revenue - COGS) / Revenue; CS is Opex there.
A5: NRR | B5: Trailing twelve months: (beginning ARR + expansion + contraction + churn) / beginning ARR for the cohort active 12 months ago. | C5: RevOps | D5: 46082 | E5: ARR Bridge B14 computes a YTD simplification, not TTM.
A6: Rule of 40 | B6: ARR growth YoY + EBITDA margin. | C6: CFO | D6: 46204 | E6: Some investor decks use revenue growth + FCF margin.
A7: Burn multiple | B7: Net burn / net new ARR for the period. | C7: CFO | D7: 46204
A8: Headcount | B8: Active employees at month end, FTE not weighted. | C8: People Ops | D8: 46034 | E8: Headcount Plan counts contractors separately; BvA snapshot pastes ending HC.
