Workbook
Name BenefitsLoad: Assumptions!$B$3
Name BonusPct: Assumptions!$B$4
Name CommissionRate: Assumptions!$B$5
Name FX_EUR_USD: Assumptions!$B$2

Sheet Cover
A1: Ardent Labs, Inc.
A2: FY2026 Budget vs Actuals, September 2026 close
A4: Prepared by | B4: FP&A (Maya Chen)
A5: Version | B5: v9, 2026-10-06
A6: Source | B6: GL export 2026-10-03 (Jan to Sep)
A7: Currency | B7: USD; EU entity converted at Assumptions!FX_EUR_USD
A8: Status | B8: Draft for CFO review
A9: Reviewer | B9: Grace Park (CFO)
A11: Change log
A12: v9 2026-10-06: September actuals appended to Actuals tab (rows added at the bottom).
A13: v8 2026-09-08: Q4 budget reforecast loaded to Budget tab as version 'FY26 RF2'.
A14: v7 2026-08-05: Dept Variance tab added at CFO request; commentary moved to its own tab.
A15: v6 2026-07-14: Benefits load changed from 20% to 22% (Treasury memo). Headcount model copied the value.

Sheet Assumptions
A1: Assumption | B1: Value | C1: Unit | D1: Owner | E1: Note
A2: FX EUR to USD (budget rate) | B2: 1.08 | C2: rate | D2: Treasury | E2: Manual input; updated quarterly. Actual monthly rates live in the Treasury FX file.
A3: Benefits load | B3: 0.22 | C3: % of salaries | D3: People Ops | E3: Changed from 20% on 2026-07-14 (Treasury memo). Headcount Plan copies this value.
A4: Bonus accrual | B4: 0.1 | C4: % of salaries | D4: FP&A | E4: Company plan at target.
A5: Commission rate | B5: 0.08 | C5: % of new ARR | D5: Sales Ops | E5: Blended; plan document v3.
A6: Statutory tax rate | B6: 0.21 | C6: rate | D6: Tax | E6: US federal only; state blended rate in the provision model.
A7: Planned monthly attrition | B7: 0.012 | C7: % of HC | D7: People Ops | E7: Used by Headcount Plan.
A8: Hosting cost per 1k API calls | B8: 0.42 | C8: USD | D8: R&D | E8: Vendor contract FY26.

Sheet COA
A1: Account | B1: Account name | C1: Category | D1: Subcategory | E1: P&L order
A2: 4000 | B2: Subscription revenue | C2: Revenue | D2: Recurring | E2: 1
A3: 4010 | B3: Professional services revenue | C3: Revenue | D3: Non-recurring | E3: 2
A4: 5000 | B4: Hosting & infrastructure | C4: COGS | D4: Cost of revenue | E4: 3
A5: 5020 | B5: Services delivery | C5: COGS | D5: Cost of revenue | E5: 4
A6: 6000 | B6: Salaries & wages | C6: Opex | D6: People | E6: 5
A7: 6010 | B7: Benefits | C7: Opex | D7: People | E7: 6
A8: 6020 | B8: Commissions | C8: Opex | D8: People | E8: 7
A9: 6030 | B9: Bonus accrual | C9: Opex | D9: People | E9: 8
A10: 6100 | B10: Software & tools | C10: Opex | D10: Non-people | E10: 9
A11: 6200 | B11: Travel & entertainment | C11: Opex | D11: Non-people | E11: 10
A12: 6300 | B12: Marketing programs | C12: Opex | D12: Non-people | E12: 11
A13: 6400 | B13: Rent & facilities | C13: Opex | D13: Non-people | E13: 12
... A17: 6900 | B17: Other opex | C17: Opex | D17: Non-people | E17: 16

Sheet Departments
A1: Dept code | B1: Department | C1: Cost center | D1: Owner | E1: VP
A2: SAL | B2: Sales | C2: CC-100 | D2: Priya Natarajan | E2: Dan Okafor (CRO)
A3: MKT | B3: Marketing | C3: CC-200 | D3: Luis Ortega | E3: Dan Okafor (CRO)
A4: CS | B4: Customer Success | C4: CC-300 | D4: Hannah Weiss | E4: Dan Okafor (CRO)
A5: RND | B5: R&D | C5: CC-400 | D5: Wei Zhang | E5: Sofia Almeida (CTO)
A6: PRD | B6: Product | C6: CC-450 | D6: Aisha Bello | E6: Sofia Almeida (CTO)
A7: GA | B7: G&A | C7: CC-500 | D7: Tom Hadley | E7: Grace Park (CFO)
A8: REV | B8: Revenue (no department) | C8: n/a | D8: Revenue accounting | E8: Grace Park (CFO)

Sheet Actuals
A1: Period | B1: Entity | C1: Department | D1: Account | E1: Product | F1: Amount | G1: Currency | H1: Source
A2: 46023 | B2: US | C2: REV | D2: 4000 | E2: Core | F2: 1717950 | G2: USD | H2: GL export 2026-10-03
A3: 46023 | B3: US | C3: REV | D3: 4000 | E3: Analytics | F3: 960991 | G3: USD | H3: GL export 2026-10-03
A4: 46023 | B4: US | C4: REV | D4: 4010 | E4: Services | F4: 270942 | G4: USD | H4: GL export 2026-10-03
A5: 46023 | B5: US | C5: SAL | D5: 6000 | F5: 330349 | G5: USD | H5: GL export 2026-10-03
A6: 46023 | B6: US | C6: SAL | D6: 6010 | F6: 71756 | G6: USD | H6: GL export 2026-10-03
A7: 46023 | B7: US | C7: SAL | D7: 6020 | F7: 113281 | G7: USD | H7: GL export 2026-10-03
A8: 46023 | B8: US | C8: SAL | D8: 6030 | F8: 31574 | G8: USD | H8: GL export 2026-10-03
A9: 46023 | B9: US | C9: SAL | D9: 6100 | F9: 18506 | G9: USD | H9: GL export 2026-10-03
A10: 46023 | B10: US | C10: SAL | D10: 6200 | F10: 24431 | G10: USD | H10: GL export 2026-10-03
A11: 46023 | B11: US | C11: SAL | D11: 6600 | F11: 10305 | G11: USD | H11: GL export 2026-10-03
A12: 46023 | B12: US | C12: SAL | D12: 6900 | F12: 6577 | G12: USD | H12: GL export 2026-10-03
A13: 46023 | B13: US | C13: MKT | D13: 6000 | F13: 155878 | G13: USD | H13: GL export 2026-10-03
A14: 46023 | B14: US | C14: MKT | D14: 6010 | F14: 31075 | G14: USD | H14: GL export 2026-10-03
A15: 46023 | B15: US | C15: MKT | D15: 6030 | F15: 15143 | G15: USD | H15: GL export 2026-10-03
A16: 46023 | B16: US | C16: MKT | D16: 6100 | F16: 8985 | G16: USD | H16: GL export 2026-10-03
... A53: 46023 | B53: US | C53: GA | D53: 6900 | F53: 4477 | G53: USD | H53: GL export 2026-10-03
A54: 46023 | B54: EU | C54: REV | D54: 4000 | E54: Core | F54: 559170 | G54: EUR | H54: GL export 2026-10-03
A55: 46023 | B55: EU | C55: REV | D55: 4000 | E55: Analytics | F55: 306718 | G55: EUR | H55: GL export 2026-10-03
A56: 46023 | B56: EU | C56: REV | D56: 4010 | E56: Services | F56: 86186 | G56: EUR | H56: GL export 2026-10-03
A57: 46023 | B57: EU | C57: SAL | D57: 6000 | F57: 101508 | G57: EUR | H57: GL export 2026-10-03
A58: 46023 | B58: EU | C58: SAL | D58: 6010 | F58: 23938 | G58: EUR | H58: GL export 2026-10-03
A59: 46023 | B59: EU | C59: SAL | D59: 6020 | F59: 37600 | G59: EUR | H59: GL export 2026-10-03
A60: 46023 | B60: EU | C60: SAL | D60: 6030 | F60: 10706 | G60: EUR | H60: GL export 2026-10-03
A61: 46023 | B61: EU | C61: SAL | D61: 6100 | F61: 6522 | G61: EUR | H61: GL export 2026-10-03
A62: 46023 | B62: EU | C62: SAL | D62: 6200 | F62: 9133 | G62: EUR | H62: GL export 2026-10-03
A63: 46023 | B63: EU | C63: SAL | D63: 6600 | F63: 3450 | G63: EUR | H63: GL export 2026-10-03
A64: 46023 | B64: EU | C64: SAL | D64: 6900 | F64: 2031 | G64: EUR | H64: GL export 2026-10-03
A65: 46023 | B65: EU | C65: MKT | D65: 6000 | F65: 52071 | G65: EUR | H65: GL export 2026-10-03
A66: 46023 | B66: EU | C66: MKT | D66: 6010 | F66: 10745 | G66: EUR | H66: GL export 2026-10-03
A67: 46023 | B67: EU | C67: MKT | D67: 6030 | F67: 4526 | G67: EUR | H67: GL export 2026-10-03
A68: 46023 | B68: EU | C68: MKT | D68: 6100 | F68: 3071 | G68: EUR | H68: GL export 2026-10-03
... A105: 46023 | B105: EU | C105: GA | D105: 6900 | F105: 1413 | G105: EUR | H105: GL export 2026-10-03
A106: 46054 | B106: US | C106: REV | D106: 4000 | E106: Core | F106: 1793657 | G106: USD | H106: GL export 2026-10-03
A107: 46054 | B107: US | C107: REV | D107: 4000 | E107: Analytics | F107: 925992 | G107: USD | H107: GL export 2026-10-03
A108: 46054 | B108: US | C108: REV | D108: 4010 | E108: Services | F108: 278721 | G108: USD | H108: GL export 2026-10-03
A109: 46054 | B109: US | C109: SAL | D109: 6000 | F109: 328328 | G109: USD | H109: GL export 2026-10-03
A110: 46054 | B110: US | C110: SAL | D110: 6010 | F110: 69971 | G110: USD | H110: GL export 2026-10-03
A111: 46054 | B111: US | C111: SAL | D111: 6020 | F111: 112332 | G111: USD | H111: GL export 2026-10-03
A112: 46054 | B112: US | C112: SAL | D112: 6030 | F112: 31552 | G112: USD | H112: GL export 2026-10-03
...

Sheet Budget
A1: Period | B1: Entity | C1: Department | D1: Account | E1: Product | F1: Amount (USD) | G1: Version
A2: 46023 | B2: US | C2: REV | D2: 4000 | E2: Core | F2: 1690000 | G2: FY26 Board
A3: 46023 | B3: US | C3: REV | D3: 4000 | E3: Analytics | F3: 910000 | G3: FY26 Board
A4: 46023 | B4: US | C4: REV | D4: 4010 | E4: Services | F4: 260000 | G4: FY26 Board
A5: 46023 | B5: US | C5: SAL | D5: 6000 | F5: 330000 | G5: FY26 Board
A6: 46023 | B6: US | C6: SAL | D6: 6010 | F6: 72600 | G6: FY26 Board
A7: 46023 | B7: US | C7: SAL | D7: 6020 | F7: 115500 | G7: FY26 Board
A8: 46023 | B8: US | C8: SAL | D8: 6030 | F8: 33000 | G8: FY26 Board
A9: 46023 | B9: US | C9: SAL | D9: 6100 | F9: 19800 | G9: FY26 Board
A10: 46023 | B10: US | C10: SAL | D10: 6200 | F10: 26400 | G10: FY26 Board
A11: 46023 | B11: US | C11: SAL | D11: 6600 | F11: 9900 | G11: FY26 Board
A12: 46023 | B12: US | C12: SAL | D12: 6900 | F12: 6600 | G12: FY26 Board
A13: 46023 | B13: US | C13: MKT | D13: 6000 | F13: 150000 | G13: FY26 Board
A14: 46023 | B14: US | C14: MKT | D14: 6010 | F14: 33000 | G14: FY26 Board
A15: 46023 | B15: US | C15: MKT | D15: 6030 | F15: 15000 | G15: FY26 Board
A16: 46023 | B16: US | C16: MKT | D16: 6100 | F16: 9000 | G16: FY26 Board
... A53: 46023 | B53: US | C53: GA | D53: 6900 | F53: 4400 | G53: FY26 Board
A54: 46023 | B54: EU | C54: REV | D54: 4000 | E54: Core | F54: 591500 | G54: FY26 Board
A55: 46023 | B55: EU | C55: REV | D55: 4000 | E55: Analytics | F55: 318500 | G55: FY26 Board
A56: 46023 | B56: EU | C56: REV | D56: 4010 | E56: Services | F56: 91000 | G56: FY26 Board
A57: 46023 | B57: EU | C57: SAL | D57: 6000 | F57: 115500 | G57: FY26 Board
A58: 46023 | B58: EU | C58: SAL | D58: 6010 | F58: 25410 | G58: FY26 Board
A59: 46023 | B59: EU | C59: SAL | D59: 6020 | F59: 40425 | G59: FY26 Board
A60: 46023 | B60: EU | C60: SAL | D60: 6030 | F60: 11550 | G60: FY26 Board
A61: 46023 | B61: EU | C61: SAL | D61: 6100 | F61: 6930 | G61: FY26 Board
A62: 46023 | B62: EU | C62: SAL | D62: 6200 | F62: 9240 | G62: FY26 Board
A63: 46023 | B63: EU | C63: SAL | D63: 6600 | F63: 3465 | G63: FY26 Board
A64: 46023 | B64: EU | C64: SAL | D64: 6900 | F64: 2310 | G64: FY26 Board
A65: 46023 | B65: EU | C65: MKT | D65: 6000 | F65: 52500 | G65: FY26 Board
A66: 46023 | B66: EU | C66: MKT | D66: 6010 | F66: 11550 | G66: FY26 Board
A67: 46023 | B67: EU | C67: MKT | D67: 6030 | F67: 5250 | G67: FY26 Board
A68: 46023 | B68: EU | C68: MKT | D68: 6100 | F68: 3150 | G68: FY26 Board
... A105: 46023 | B105: EU | C105: GA | D105: 6900 | F105: 1540 | G105: FY26 Board
A106: 46054 | B106: US | C106: REV | D106: 4000 | E106: Core | F106: 1723800 | G106: FY26 Board
A107: 46054 | B107: US | C107: REV | D107: 4000 | E107: Analytics | F107: 928200 | G107: FY26 Board
A108: 46054 | B108: US | C108: REV | D108: 4010 | E108: Services | F108: 265200 | G108: FY26 Board
A109: 46054 | B109: US | C109: SAL | D109: 6000 | F109: 333300 | G109: FY26 Board
A110: 46054 | B110: US | C110: SAL | D110: 6010 | F110: 73326 | G110: FY26 Board
A111: 46054 | B111: US | C111: SAL | D111: 6020 | F111: 116655 | G111: FY26 Board
A112: 46054 | B112: US | C112: SAL | D112: 6030 | F112: 33330 | G112: FY26 Board
...

Sheet BvA Summary
A1: Ardent Labs, Inc. FY2026 Budget vs Actuals (USD)
A2: September 2026 close. EU entity converted at FX_EUR_USD. Prepared by FP&A.
A3: period key (hidden) | D3: 46204 | E3: 46204 | F3: 46235 | G3: 46235 | H3: 46266 | I3: 46266 | J3: 46266 | K3: 46266
A4: Account | B4: Account name | C4: Category | D4: Jul-26 Actual | E4: Jul-26 Budget | F4: Aug-26 Actual | G4: Aug-26 Budget | H4: Sep-26 Actual | I4: Sep-26 Budget | J4: YTD Actual | K4: YTD Budget | L4: YTD Variance | M4: YTD Var %
A5: 4000 | B5: =VLOOKUP($A5,COA!$A$2:$E$30,2,FALSE) -> Subscription revenue | C5: =VLOOKUP($A5,COA!$A$2:$E$30,3,FALSE) -> Revenue | D5: =SUMIFS(Actuals!$F$2:$F$891,Actuals!$D$2:$D$891,$A5,Actuals!$A$2:$A$891,D$3,Actuals!$B$2:$B$891,"US")+SUMIFS(Actuals!$F$2:$F$891,Actuals!$D$2:$D$891,$A5,Actuals!$A$2:$A$891,D$3,Actuals!$B$2:$B$891,"EU")*FX_EUR_USD -> 4008528.6 | E5: =SUMIFS(Budget!$F$2:$F$1300,Budget!$A$2:$A$1300,E$3,Budget!$D$2:$D$1300,$A5) -> 3952830 | F5: =SUMIFS(Actuals!$F$2:$F$891,Actuals!$D$2:$D$891,$A5,Actuals!$A$2:$A$891,F$3,Actuals!$B$2:$B$891,"US")+SUMIFS(Actuals!$F$2:$F$891,Actuals!$D$2:$D$891,$A5,Actuals!$A$2:$A$891,F$3,Actuals!$B$2:$B$891,"EU")*FX_EUR_USD -> 4112680.4 | G5: =SUMIFS(Budget!$F$2:$F$1300,Budget!$A$2:$A$1300,G$3,Budget!$D$2:$D$1300,$A5) -> 4031887 | H5: =SUMIFS(Actuals!$F$2:$F$891,Actuals!$D$2:$D$891,$A5,Actuals!$A$2:$A$891,H$3,Actuals!$B$2:$B$891,"US")+SUMIFS(Actuals!$F$2:$F$891,Actuals!$D$2:$D$891,$A5,Actuals!$A$2:$A$891,H$3,Actuals!$B$2:$B$891,"EU")*FX_EUR_USD -> 4180963.1 | I5: =SUMIFS(Budget!$F$2:$F$1300,Budget!$A$2:$A$1300,I$3,Budget!$D$2:$D$1300,$A5) -> 4112525 | J5: =SUMIFS(Actuals!$F$2:$F$891,Actuals!$D$2:$D$891,$A5,Actuals!$B$2:$B$891,"US")+SUMIFS(Actuals!$F$2:$F$891,Actuals!$D$2:$D$891,$A5,Actuals!$B$2:$B$891,"EU")*FX_EUR_USD -> 35020993 | K5: =SUMIFS(Budget!$F$2:$F$1300,Budget!$A$2:$A$1300,"<="&K$3,Budget!$D$2:$D$1300,$A5) -> 34238749 | L5: =J5-K5 -> 782243.6 | M5: =IFERROR(L5/K5,0) -> 0.022846734
A6: 4010 | B6: =VLOOKUP($A6,COA!$A$2:$E$30,2,FALSE) -> Professional services revenue | C6: =VLOOKUP($A6,COA!$A$2:$E$30,3,FALSE) -> Revenue | D6: =SUMIFS(Actuals!$F$2:$F$891,Actuals!$D$2:$D$891,$A6,Actuals!$A$2:$A$891,D$3,Actuals!$B$2:$B$891,"US")+SUMIFS(Actuals!$F$2:$F$891,Actuals!$D$2:$D$891,$A6,Actuals!$A$2:$A$891,D$3,Actuals!$B$2:$B$891,"EU")*FX_EUR_USD -> 401215.24 | E6: =SUMIFS(Budget!$F$2:$F$1300,Budget!$A$2:$A$1300,E$3,Budget!$D$2:$D$1300,$A6) -> 395283 | F6: =SUMIFS(Actuals!$F$2:$F$891,Actuals!$D$2:$D$891,$A6,Actuals!$A$2:$A$891,F$3,Actuals!$B$2:$B$891,"US")+SUMIFS(Actuals!$F$2:$F$891,Actuals!$D$2:$D$891,$A6,Actuals!$A$2:$A$891,F$3,Actuals!$B$2:$B$891,"EU")*FX_EUR_USD -> 415668.08 | G6: =SUMIFS(Budget!$F$2:$F$1300,Budget!$A$2:$A$1300,G$3,Budget!$D$2:$D$1300,$A6) -> 403188 | H6: =SUMIFS(Actuals!$F$2:$F$891,Actuals!$D$2:$D$891,$A6,Actuals!$A$2:$A$891,H$3,Actuals!$B$2:$B$891,"US")+SUMIFS(Actuals!$F$2:$F$891,Actuals!$D$2:$D$891,$A6,Actuals!$A$2:$A$891,H$3,Actuals!$B$2:$B$891,"EU")*FX_EUR_USD -> 420696.92 | I6: =SUMIFS(Budget!$F$2:$F$1300,Budget!$A$2:$A$1300,I$3,Budget!$D$2:$D$1300,$A6) -> 411252 | J6: =SUMIFS(Actuals!$F$2:$F$891,Actuals!$D$2:$D$891,$A6,Actuals!$B$2:$B$891,"US")+SUMIFS(Actuals!$F$2:$F$891,Actuals!$D$2:$D$891,$A6,Actuals!$B$2:$B$891,"EU")*FX_EUR_USD -> 3518583.9 | K6: =SUMIFS(Budget!$F$2:$F$1300,Budget!$A$2:$A$1300,"<="&K$3,Budget!$D$2:$D$1300,$A6) -> 3423872 | L6: =J6-K6 -> 94711.92 | M6: =IFERROR(L6/K6,0) -> 0.027662226
B7: Total Revenue | D7: =SUM(D5:D6) -> 4409743.8 | E7: =SUM(E5:E6) -> 4348113 | F7: =SUM(F5:F6) -> 4528348.4 | G7: =SUM(G5:G6) -> 4435075 | H7: =SUM(H5:H6) -> 4601660 | I7: =SUM(I5:I6) -> 4523777 | J7: =SUM(J5:J6) -> 38539577 | K7: =SUM(K5:K6) -> 37662621 | L7: =SUM(L5:L6) -> 876955.52 | M7: =IFERROR(L7/K7,0) -> 0.023284506
A8: 5000 | B8: =VLOOKUP($A8,COA!$A$2:$E$30,2,FALSE) -> Hosting & infrastructure | C8: =VLOOKUP($A8,COA!$A$2:$E$30,3,FALSE) -> COGS | D8: =SUMIFS(Actuals!$F$2:$F$891,Actuals!$D$2:$D$891,$A8,Actuals!$A$2:$A$891,D$3,Actuals!$B$2:$B$891,"US")+SUMIFS(Actuals!$F$2:$F$891,Actuals!$D$2:$D$891,$A8,Actuals!$A$2:$A$891,D$3,Actuals!$B$2:$B$891,"EU")*FX_EUR_USD -> 728344.36 | E8: =SUMIFS(Budget!$F$2:$F$1300,Budget!$A$2:$A$1300,E$3,Budget!$D$2:$D$1300,$A8) -> 744120 | F8: =SUMIFS(Actuals!$F$2:$F$891,Actuals!$D$2:$D$891,$A8,Actuals!$A$2:$A$891,F$3,Actuals!$B$2:$B$891,"US")+SUMIFS(Actuals!$F$2:$F$891,Actuals!$D$2:$D$891,$A8,Actuals!$A$2:$A$891,F$3,Actuals!$B$2:$B$891,"EU")*FX_EUR_USD -> 775664 | G8: =SUMIFS(Budget!$F$2:$F$1300,Budget!$A$2:$A$1300,G$3,Budget!$D$2:$D$1300,$A8) -> 751140 | H8: =SUMIFS(Actuals!$F$2:$F$891,Actuals!$D$2:$D$891,$A8,Actuals!$A$2:$A$891,H$3,Actuals!$B$2:$B$891,"US")+SUMIFS(Actuals!$F$2:$F$891,Actuals!$D$2:$D$891,$A8,Actuals!$A$2:$A$891,H$3,Actuals!$B$2:$B$891,"EU")*FX_EUR_USD -> 546141 | I8: =SUMIFS(Budget!$F$2:$F$1300,Budget!$A$2:$A$1300,I$3,Budget!$D$2:$D$1300,$A8) -> 758160 | J8: =SUMIFS(Actuals!$F$2:$F$891,Actuals!$D$2:$D$891,$A8,Actuals!$B$2:$B$891,"US")+SUMIFS(Actuals!$F$2:$F$891,Actuals!$D$2:$D$891,$A8,Actuals!$B$2:$B$891,"EU")*FX_EUR_USD -> 6305638.6 | K8: =SUMIFS(Budget!$F$2:$F$1300,Budget!$A$2:$A$1300,"<="&K$3,Budget!$D$2:$D$1300,$A8) -> 6570720 | L8: =J8-K8 -> -265081.4 | M8: =IFERROR(L8/K8,0) -> -0.040342824
A9: 5020 | B9: =VLOOKUP($A9,COA!$A$2:$E$30,2,FALSE) -> Services delivery | C9: =VLOOKUP($A9,COA!$A$2:$E$30,3,FALSE) -> COGS | D9: =SUMIFS(Actuals!$F$2:$F$891,Actuals!$D$2:$D$891,$A9,Actuals!$A$2:$A$891,D$3,Actuals!$B$2:$B$891,"US")+SUMIFS(Actuals!$F$2:$F$891,Actuals!$D$2:$D$891,$A9,Actuals!$A$2:$A$891,D$3,Actuals!$B$2:$B$891,"EU")*FX_EUR_USD -> 100649.28 | E9: =SUMIFS(Budget!$F$2:$F$1300,Budget!$A$2:$A$1300,E$3,Budget!$D$2:$D$1300,$A9) -> 97308 | F9: =SUMIFS(Actuals!$F$2:$F$891,Actuals!$D$2:$D$891,$A9,Actuals!$A$2:$A$891,F$3,Actuals!$B$2:$B$891,"US")+SUMIFS(Actuals!$F$2:$F$891,Actuals!$D$2:$D$891,$A9,Actuals!$A$2:$A$891,F$3,Actuals!$B$2:$B$891,"EU")*FX_EUR_USD -> 100208.44 | G9: =SUMIFS(Budget!$F$2:$F$1300,Budget!$A$2:$A$1300,G$3,Budget!$D$2:$D$1300,$A9) -> 98226 | H9: =SUMIFS(Actuals!$F$2:$F$891,Actuals!$D$2:$D$891,$A9,Actuals!$A$2:$A$891,H$3,Actuals!$B$2:$B$891,"US")+SUMIFS(Actuals!$F$2:$F$891,Actuals!$D$2:$D$891,$A9,Actuals!$A$2:$A$891,H$3,Actuals!$B$2:$B$891,"EU")*FX_EUR_USD -> 72170 | I9: =SUMIFS(Budget!$F$2:$F$1300,Budget!$A$2:$A$1300,I$3,Budget!$D$2:$D$1300,$A9) -> 99144 | J9: =SUMIFS(Actuals!$F$2:$F$891,Actuals!$D$2:$D$891,$A9,Actuals!$B$2:$B$891,"US")+SUMIFS(Actuals!$F$2:$F$891,Actuals!$D$2:$D$891,$A9,Actuals!$B$2:$B$891,"EU")*FX_EUR_USD -> 850891.72 | K9: =SUMIFS(Budget!$F$2:$F$1300,Budget!$A$2:$A$1300,"<="&K$3,Budget!$D$2:$D$1300,$A9) -> 859248 | L9: =J9-K9 -> -8356.28 | M9: =IFERROR(L9/K9,0) -> -0.0097251085
B10: Total COGS | D10: =SUM(D8:D9) -> 828993.64 | E10: =SUM(E8:E9) -> 841428 | F10: =SUM(F8:F9) -> 875872.44 | G10: =SUM(G8:G9) -> 849366 | H10: =SUM(H8:H9) -> 618311 | I10: =SUM(I8:I9) -> 857304 | J10: =SUM(J8:J9) -> 7156530.3 | K10: =SUM(K8:K9) -> 7429968 | L10: =SUM(L8:L9) -> -273437.68 | M10: =IFERROR(L10/K10,0) -> -0.036802
B11: Gross profit | D11: =D7-D10 -> 3580750.2 | E11: =E7-E10 -> 3506685 | F11: =F7-F10 -> 3652476 | G11: =G7-G10 -> 3585709 | H11: =H7-H10 -> 3983349 | I11: =I7-I10 -> 3666473 | J11: =J7-J10 -> 31383046 | K11: =K7-K10 -> 30232653 | L11: =L7-L10 -> 1150393.2 | M11: =IFERROR(L11/K11,0) -> 0.038051348
B12: Gross margin % | D12: =IFERROR(D11/D7,0) -> 0.81200866 | E12: =IFERROR(E11/E7,0) -> 0.80648433 | F12: =IFERROR(F11/F7,0) -> 0.80658016 | G12: =IFERROR(G11/G7,0) -> 0.80848892 | H12: =IFERROR(H11/H7,0) -> 0.86563306 | I12: =IFERROR(I11/I7,0) -> 0.81048933 | J12: =IFERROR(J11/J7,0) -> 0.81430698 | K12: =IFERROR(K11/K7,0) -> 0.80272302 | L12: =J12-K12 -> 0.011583957
A13: 6000 | B13: =VLOOKUP($A13,COA!$A$2:$E$30,2,FALSE) -> Salaries & wages | C13: =VLOOKUP($A13,COA!$A$2:$E$30,3,FALSE) -> Opex | D13: =SUMIFS(Actuals!$F$2:$F$891,Actuals!$D$2:$D$891,$A13,Actuals!$A$2:$A$891,D$3,Actuals!$B$2:$B$891,"US")+SUMIFS(Actuals!$F$2:$F$891,Actuals!$D$2:$D$891,$A13,Actuals!$A$2:$A$891,D$3,Actuals!$B$2:$B$891,"EU")*FX_EUR_USD -> 2128809.3 | E13: =SUMIFS(Budget!$F$2:$F$1300,Budget!$A$2:$A$1300,E$3,Budget!$D$2:$D$1300,$A13) -> 2189430 | F13: =SUMIFS(Actuals!$F$2:$F$891,Actuals!$D$2:$D$891,$A13,Actuals!$A$2:$A$891,F$3,Actuals!$B$2:$B$891,"US")+SUMIFS(Actuals!$F$2:$F$891,Actuals!$D$2:$D$891,$A13,Actuals!$A$2:$A$891,F$3,Actuals!$B$2:$B$891,"EU")*FX_EUR_USD -> 2117981.8 | G13: =SUMIFS(Budget!$F$2:$F$1300,Budget!$A$2:$A$1300,G$3,Budget!$D$2:$D$1300,$A13) -> 2210085 | H13: =SUMIFS(Actuals!$F$2:$F$891,Actuals!$D$2:$D$891,$A13,Actuals!$A$2:$A$891,H$3,Actuals!$B$2:$B$891,"US")+SUMIFS(Actuals!$F$2:$F$891,Actuals!$D$2:$D$891,$A13,Actuals!$A$2:$A$891,H$3,Actuals!$B$2:$B$891,"EU")*FX_EUR_USD -> 1747417.2 | I13: =SUMIFS(Budget!$F$2:$F$1300,Budget!$A$2:$A$1300,I$3,Budget!$D$2:$D$1300,$A13) -> 2230740 | J13: =SUMIFS(Actuals!$F$2:$F$891,Actuals!$D$2:$D$891,$A13,Actuals!$B$2:$B$891,"US")+SUMIFS(Actuals!$F$2:$F$891,Actuals!$D$2:$D$891,$A13,Actuals!$B$2:$B$891,"EU")*FX_EUR_USD -> 18495769 | K13: =SUMIFS(Budget!$F$2:$F$1300,Budget!$A$2:$A$1300,"<="&K$3,Budget!$D$2:$D$1300,$A13) -> 19333080 | L13: =J13-K13 -> -837311.44 | M13: =IFERROR(L13/K13,0) -> -0.04330978
A14: 6010 | B14: =VLOOKUP($A14,COA!$A$2:$E$30,2,FALSE) -> Benefits | C14: =VLOOKUP($A14,COA!$A$2:$E$30,3,FALSE) -> Opex | D14: =SUMIFS(Actuals!$F$2:$F$891,Actuals!$D$2:$D$891,$A14,Actuals!$A$2:$A$891,D$3,Actuals!$B$2:$B$891,"US")+SUMIFS(Actuals!$F$2:$F$891,Actuals!$D$2:$D$891,$A14,Actuals!$A$2:$A$891,D$3,Actuals!$B$2:$B$891,"EU")*FX_EUR_USD -> 464797.28 | E14: =SUMIFS(Budget!$F$2:$F$1300,Budget!$A$2:$A$1300,E$3,Budget!$D$2:$D$1300,$A14) -> 481674 | F14: =SUMIFS(Actuals!$F$2:$F$891,Actuals!$D$2:$D$891,$A14,Actuals!$A$2:$A$891,F$3,Actuals!$B$2:$B$891,"US")+SUMIFS(Actuals!$F$2:$F$891,Actuals!$D$2:$D$891,$A14,Actuals!$A$2:$A$891,F$3,Actuals!$B$2:$B$891,"EU")*FX_EUR_USD -> 466670.76 | G14: =SUMIFS(Budget!$F$2:$F$1300,Budget!$A$2:$A$1300,G$3,Budget!$D$2:$D$1300,$A14) -> 486219 | H14: =SUMIFS(Actuals!$F$2:$F$891,Actuals!$D$2:$D$891,$A14,Actuals!$A$2:$A$891,H$3,Actuals!$B$2:$B$891,"US")+SUMIFS(Actuals!$F$2:$F$891,Actuals!$D$2:$D$891,$A14,Actuals!$A$2:$A$891,H$3,Actuals!$B$2:$B$891,"EU")*FX_EUR_USD -> 379578.88 | I14: =SUMIFS(Budget!$F$2:$F$1300,Budget!$A$2:$A$1300,I$3,Budget!$D$2:$D$1300,$A14) -> 490762 | J14: =SUMIFS(Actuals!$F$2:$F$891,Actuals!$D$2:$D$891,$A14,Actuals!$B$2:$B$891,"US")+SUMIFS(Actuals!$F$2:$F$891,Actuals!$D$2:$D$891,$A14,Actuals!$B$2:$B$891,"EU")*FX_EUR_USD -> 4070832 | K14: =SUMIFS(Budget!$F$2:$F$1300,Budget!$A$2:$A$1300,"<="&K$3,Budget!$D$2:$D$1300,$A14) -> 4253276 | L14: =J14-K14 -> -182444 | M14: =IFERROR(L14/K14,0) -> -0.042894936
A15: 6020 | B15: =VLOOKUP($A15,COA!$A$2:$E$30,2,FALSE) -> Commissions | C15: =VLOOKUP($A15,COA!$A$2:$E$30,3,FALSE) -> Opex | D15: =SUMIFS(Actuals!$F$2:$F$891,Actuals!$D$2:$D$891,$A15,Actuals!$A$2:$A$891,D$3,Actuals!$B$2:$B$891,"US")+SUMIFS(Actuals!$F$2:$F$891,Actuals!$D$2:$D$891,$A15,Actuals!$A$2:$A$891,D$3,Actuals!$B$2:$B$891,"EU")*FX_EUR_USD -> 170956.8 | E15: =SUMIFS(Budget!$F$2:$F$1300,Budget!$A$2:$A$1300,E$3,Budget!$D$2:$D$1300,$A15) -> 165280 | F15: =SUMIFS(Actuals!$F$2:$F$891,Actuals!$D$2:$D$891,$A15,Actuals!$A$2:$A$891,F$3,Actuals!$B$2:$B$891,"US")+SUMIFS(Actuals!$F$2:$F$891,Actuals!$D$2:$D$891,$A15,Actuals!$A$2:$A$891,F$3,Actuals!$B$2:$B$891,"EU")*FX_EUR_USD -> 170697.6 | G15: =SUMIFS(Budget!$F$2:$F$1300,Budget!$A$2:$A$1300,G$3,Budget!$D$2:$D$1300,$A15) -> 166840 | H15: =SUMIFS(Actuals!$F$2:$F$891,Actuals!$D$2:$D$891,$A15,Actuals!$A$2:$A$891,H$3,Actuals!$B$2:$B$891,"US")+SUMIFS(Actuals!$F$2:$F$891,Actuals!$D$2:$D$891,$A15,Actuals!$A$2:$A$891,H$3,Actuals!$B$2:$B$891,"EU")*FX_EUR_USD -> 167150.76 | I15: =SUMIFS(Budget!$F$2:$F$1300,Budget!$A$2:$A$1300,I$3,Budget!$D$2:$D$1300,$A15) -> 168399 | J15: =SUMIFS(Actuals!$F$2:$F$891,Actuals!$D$2:$D$891,$A15,Actuals!$B$2:$B$891,"US")+SUMIFS(Actuals!$F$2:$F$891,Actuals!$D$2:$D$891,$A15,Actuals!$B$2:$B$891,"EU")*FX_EUR_USD -> 1456261.6 | K15: =SUMIFS(Budget!$F$2:$F$1300,Budget!$A$2:$A$1300,"<="&K$3,Budget!$D$2:$D$1300,$A15) -> 1459457 | L15: =J15-K15 -> -3195.44 | M15: =IFERROR(L15/K15,0) -> -0.0021894718
A16: 6030 | B16: =VLOOKUP($A16,COA!$A$2:$E$30,2,FALSE) -> Bonus accrual | C16: =VLOOKUP($A16,COA!$A$2:$E$30,3,FALSE) -> Opex | D16: =SUMIFS(Actuals!$F$2:$F$891,Actuals!$D$2:$D$891,$A16,Actuals!$A$2:$A$891,D$3,Actuals!$B$2:$B$891,"US")+SUMIFS(Actuals!$F$2:$F$891,Actuals!$D$2:$D$891,$A16,Actuals!$A$2:$A$891,D$3,Actuals!$B$2:$B$891,"EU")*FX_EUR_USD -> 211441.4 | E16: =SUMIFS(Budget!$F$2:$F$1300,Budget!$A$2:$A$1300,E$3,Budget!$D$2:$D$1300,$A16) -> 218943 | F16: =SUMIFS(Actuals!$F$2:$F$891,Actuals!$D$2:$D$891,$A16,Actuals!$A$2:$A$891,F$3,Actuals!$B$2:$B$891,"US")+SUMIFS(Actuals!$F$2:$F$891,Actuals!$D$2:$D$891,$A16,Actuals!$A$2:$A$891,F$3,Actuals!$B$2:$B$891,"EU")*FX_EUR_USD -> 217581.2 | G16: =SUMIFS(Budget!$F$2:$F$1300,Budget!$A$2:$A$1300,G$3,Budget!$D$2:$D$1300,$A16) -> 221008 | H16: =SUMIFS(Actuals!$F$2:$F$891,Actuals!$D$2:$D$891,$A16,Actuals!$A$2:$A$891,H$3,Actuals!$B$2:$B$891,"US")+SUMIFS(Actuals!$F$2:$F$891,Actuals!$D$2:$D$891,$A16,Actuals!$A$2:$A$891,H$3,Actuals!$B$2:$B$891,"EU")*FX_EUR_USD -> 164450 | I16: =SUMIFS(Budget!$F$2:$F$1300,Budget!$A$2:$A$1300,I$3,Budget!$D$2:$D$1300,$A16) -> 223074 | J16: =SUMIFS(Actuals!$F$2:$F$891,Actuals!$D$2:$D$891,$A16,Actuals!$B$2:$B$891,"US")+SUMIFS(Actuals!$F$2:$F$891,Actuals!$D$2:$D$891,$A16,Actuals!$B$2:$B$891,"EU")*FX_EUR_USD -> 1853027.5 | K16: =SUMIFS(Budget!$F$2:$F$1300,Budget!$A$2:$A$1300,"<="&K$3,Budget!$D$2:$D$1300,$A16) -> 1933308 | L16: =J16-K16 -> -80280.52 | M16: =IFERROR(L16/K16,0) -> -0.041524951
A17: 6100 | B17: =VLOOKUP($A17,COA!$A$2:$E$30,2,FALSE) -> Software & tools | C17: =VLOOKUP($A17,COA!$A$2:$E$30,3,FALSE) -> Opex | D17: =SUMIFS(Actuals!$F$2:$F$891,Actuals!$D$2:$D$891,$A17,Actuals!$A$2:$A$891,D$3,Actuals!$B$2:$B$891,"US")+SUMIFS(Actuals!$F$2:$F$891,Actuals!$D$2:$D$891,$A17,Actuals!$A$2:$A$891,D$3,Actuals!$B$2:$B$891,"EU")*FX_EUR_USD -> 132806 | E17: =SUMIFS(Budget!$F$2:$F$1300,Budget!$A$2:$A$1300,E$3,Budget!$D$2:$D$1300,$A17) -> 131365 | F17: =SUMIFS(Actuals!$F$2:$F$891,Actuals!$D$2:$D$891,$A17,Actuals!$A$2:$A$891,F$3,Actuals!$B$2:$B$891,"US")+SUMIFS(Actuals!$F$2:$F$891,Actuals!$D$2:$D$891,$A17,Actuals!$A$2:$A$891,F$3,Actuals!$B$2:$B$891,"EU")*FX_EUR_USD -> 128506.32 | G17: =SUMIFS(Budget!$F$2:$F$1300,Budget!$A$2:$A$1300,G$3,Budget!$D$2:$D$1300,$A17) -> 132604 | H17: =SUMIFS(Actuals!$F$2:$F$891,Actuals!$D$2:$D$891,$A17,Actuals!$A$2:$A$891,H$3,Actuals!$B$2:$B$891,"US")+SUMIFS(Actuals!$F$2:$F$891,Actuals!$D$2:$D$891,$A17,Actuals!$A$2:$A$891,H$3,Actuals!$B$2:$B$891,"EU")*FX_EUR_USD -> 100129 | I17: =SUMIFS(Budget!$F$2:$F$1300,Budget!$A$2:$A$1300,I$3,Budget!$D$2:$D$1300,$A17) -> 133845 | J17: =SUMIFS(Actuals!$F$2:$F$891,Actuals!$D$2:$D$891,$A17,Actuals!$B$2:$B$891,"US")+SUMIFS(Actuals!$F$2:$F$891,Actuals!$D$2:$D$891,$A17,Actuals!$B$2:$B$891,"EU")*FX_EUR_USD -> 1124933.4 | K17: =SUMIFS(Budget!$F$2:$F$1300,Budget!$A$2:$A$1300,"<="&K$3,Budget!$D$2:$D$1300,$A17) -> 1159983 | L17: =J17-K17 -> -35049.6 | M17: =IFERROR(L17/K17,0) -> -0.030215615
A18: 6200 | B18: =VLOOKUP($A18,COA!$A$2:$E$30,2,FALSE) -> Travel & entertainment | C18: =VLOOKUP($A18,COA!$A$2:$E$30,3,FALSE) -> Opex | D18: =SUMIFS(Actuals!$F$2:$F$891,Actuals!$D$2:$D$891,$A18,Actuals!$A$2:$A$891,D$3,Actuals!$B$2:$B$891,"US")+SUMIFS(Actuals!$F$2:$F$891,Actuals!$D$2:$D$891,$A18,Actuals!$A$2:$A$891,D$3,Actuals!$B$2:$B$891,"EU")*FX_EUR_USD -> 114627.32 | E18: =SUMIFS(Budget!$F$2:$F$1300,Budget!$A$2:$A$1300,E$3,Budget!$D$2:$D$1300,$A18) -> 115053 | F18: =SUMIFS(Actuals!$F$2:$F$891,Actuals!$D$2:$D$891,$A18,Actuals!$A$2:$A$891,F$3,Actuals!$B$2:$B$891,"US")+SUMIFS(Actuals!$F$2:$F$891,Actuals!$D$2:$D$891,$A18,Actuals!$A$2:$A$891,F$3,Actuals!$B$2:$B$891,"EU")*FX_EUR_USD -> 113484.6 | G18: =SUMIFS(Budget!$F$2:$F$1300,Budget!$A$2:$A$1300,G$3,Budget!$D$2:$D$1300,$A18) -> 116139 | H18: =SUMIFS(Actuals!$F$2:$F$891,Actuals!$D$2:$D$891,$A18,Actuals!$A$2:$A$891,H$3,Actuals!$B$2:$B$891,"US")+SUMIFS(Actuals!$F$2:$F$891,Actuals!$D$2:$D$891,$A18,Actuals!$A$2:$A$891,H$3,Actuals!$B$2:$B$891,"EU")*FX_EUR_USD -> 85342 | I18: =SUMIFS(Budget!$F$2:$F$1300,Budget!$A$2:$A$1300,I$3,Budget!$D$2:$D$1300,$A18) -> 117222 | J18: =SUMIFS(Actuals!$F$2:$F$891,Actuals!$D$2:$D$891,$A18,Actuals!$B$2:$B$891,"US")+SUMIFS(Actuals!$F$2:$F$891,Actuals!$D$2:$D$891,$A18,Actuals!$B$2:$B$891,"EU")*FX_EUR_USD -> 979542.6 | K18: =SUMIFS(Budget!$F$2:$F$1300,Budget!$A$2:$A$1300,"<="&K$3,Budget!$D$2:$D$1300,$A18) -> 1015935 | L18: =J18-K18 -> -36392.4 | M18: =IFERROR(L18/K18,0) -> -0.035821583
A19: 6300 | B19: =VLOOKUP($A19,COA!$A$2:$E$30,2,FALSE) -> Marketing programs | C19: =VLOOKUP($A19,COA!$A$2:$E$30,3,FALSE) -> Opex | D19: =SUMIFS(Actuals!$F$2:$F$891,Actuals!$D$2:$D$891,$A19,Actuals!$A$2:$A$891,D$3,Actuals!$B$2:$B$891,"US")+SUMIFS(Actuals!$F$2:$F$891,Actuals!$D$2:$D$891,$A19,Actuals!$A$2:$A$891,D$3,Actuals!$B$2:$B$891,"EU")*FX_EUR_USD -> 286446.12 | E19: =SUMIFS(Budget!$F$2:$F$1300,Budget!$A$2:$A$1300,E$3,Budget!$D$2:$D$1300,$A19) -> 289778 | F19: =SUMIFS(Actuals!$F$2:$F$891,Actuals!$D$2:$D$891,$A19,Actuals!$A$2:$A$891,F$3,Actuals!$B$2:$B$891,"US")+SUMIFS(Actuals!$F$2:$F$891,Actuals!$D$2:$D$891,$A19,Actuals!$A$2:$A$891,F$3,Actuals!$B$2:$B$891,"EU")*FX_EUR_USD -> 292313.08 | G19: =SUMIFS(Budget!$F$2:$F$1300,Budget!$A$2:$A$1300,G$3,Budget!$D$2:$D$1300,$A19) -> 292511 | H19: =SUMIFS(Actuals!$F$2:$F$891,Actuals!$D$2:$D$891,$A19,Actuals!$A$2:$A$891,H$3,Actuals!$B$2:$B$891,"US")+SUMIFS(Actuals!$F$2:$F$891,Actuals!$D$2:$D$891,$A19,Actuals!$A$2:$A$891,H$3,Actuals!$B$2:$B$891,"EU")*FX_EUR_USD -> 193496 | I19: =SUMIFS(Budget!$F$2:$F$1300,Budget!$A$2:$A$1300,I$3,Budget!$D$2:$D$1300,$A19) -> 295245 | J19: =SUMIFS(Actuals!$F$2:$F$891,Actuals!$D$2:$D$891,$A19,Actuals!$B$2:$B$891,"US")+SUMIFS(Actuals!$F$2:$F$891,Actuals!$D$2:$D$891,$A19,Actuals!$B$2:$B$891,"EU")*FX_EUR_USD -> 2990335.2 | K19: =SUMIFS(Budget!$F$2:$F$1300,Budget!$A$2:$A$1300,"<="&K$3,Budget!$D$2:$D$1300,$A19) -> 2558790 | L19: =J19-K19 -> 431545.24 | M19: =IFERROR(L19/K19,0) -> 0.16865207
A20: 6400 | B20: =VLOOKUP($A20,COA!$A$2:$E$30,2,FALSE) -> Rent & facilities | C20: =VLOOKUP($A20,COA!$A$2:$E$30,3,FALSE) -> Opex | D20: =SUMIFS(Actuals!$F$2:$F$891,Actuals!$D$2:$D$891,$A20,Actuals!$A$2:$A$891,D$3,Actuals!$B$2:$B$891,"US")+SUMIFS(Actuals!$F$2:$F$891,Actuals!$D$2:$D$891,$A20,Actuals!$A$2:$A$891,D$3,Actuals!$B$2:$B$891,"EU")*FX_EUR_USD -> 182917.12 | E20: =SUMIFS(Budget!$F$2:$F$1300,Budget!$A$2:$A$1300,E$3,Budget!$D$2:$D$1300,$A20) -> 182596 | F20: =SUMIFS(Actuals!$F$2:$F$891,Actuals!$D$2:$D$891,$A20,Actuals!$A$2:$A$891,F$3,Actuals!$B$2:$B$891,"US")+SUMIFS(Actuals!$F$2:$F$891,Actuals!$D$2:$D$891,$A20,Actuals!$A$2:$A$891,F$3,Actuals!$B$2:$B$891,"EU")*FX_EUR_USD -> 181835.04 | G20: =SUMIFS(Budget!$F$2:$F$1300,Budget!$A$2:$A$1300,G$3,Budget!$D$2:$D$1300,$A20) -> 184318 | H20: =SUMIFS(Actuals!$F$2:$F$891,Actuals!$D$2:$D$891,$A20,Actuals!$A$2:$A$891,H$3,Actuals!$B$2:$B$891,"US")+SUMIFS(Actuals!$F$2:$F$891,Actuals!$D$2:$D$891,$A20,Actuals!$A$2:$A$891,H$3,Actuals!$B$2:$B$891,"EU")*FX_EUR_USD -> 151551 | I20: =SUMIFS(Budget!$F$2:$F$1300,Budget!$A$2:$A$1300,I$3,Budget!$D$2:$D$1300,$A20) -> 186041 | J20: =SUMIFS(Actuals!$F$2:$F$891,Actuals!$D$2:$D$891,$A20,Actuals!$B$2:$B$891,"US")+SUMIFS(Actuals!$F$2:$F$891,Actuals!$D$2:$D$891,$A20,Actuals!$B$2:$B$891,"EU")*FX_EUR_USD -> 1593217 | K20: =SUMIFS(Budget!$F$2:$F$1300,Budget!$A$2:$A$1300,"<="&K$3,Budget!$D$2:$D$1300,$A20) -> 1612354 | L20: =J20-K20 -> -19137 | M20: =IFERROR(L20/K20,0) -> -0.011868982
A21: 6500 | B21: =VLOOKUP($A21,COA!$A$2:$E$30,2,FALSE) -> Professional fees | C21: =VLOOKUP($A21,COA!$A$2:$E$30,3,FALSE) -> Opex | D21: =SUMIFS(Actuals!$F$2:$F$891,Actuals!$D$2:$D$891,$A21,Actuals!$A$2:$A$891,D$3,Actuals!$B$2:$B$891,"US")+SUMIFS(Actuals!$F$2:$F$891,Actuals!$D$2:$D$891,$A21,Actuals!$A$2:$A$891,D$3,Actuals!$B$2:$B$891,"EU")*FX_EUR_USD -> 99174.76 | E21: =SUMIFS(Budget!$F$2:$F$1300,Budget!$A$2:$A$1300,E$3,Budget!$D$2:$D$1300,$A21) -> 100742 | F21: =SUMIFS(Actuals!$F$2:$F$891,Actuals!$D$2:$D$891,$A21,Actuals!$A$2:$A$891,F$3,Actuals!$B$2:$B$891,"US")+SUMIFS(Actuals!$F$2:$F$891,Actuals!$D$2:$D$891,$A21,Actuals!$A$2:$A$891,F$3,Actuals!$B$2:$B$891,"EU")*FX_EUR_USD -> 107207.28 | G21: =SUMIFS(Budget!$F$2:$F$1300,Budget!$A$2:$A$1300,G$3,Budget!$D$2:$D$1300,$A21) -> 101693 | H21: =SUMIFS(Actuals!$F$2:$F$891,Actuals!$D$2:$D$891,$A21,Actuals!$A$2:$A$891,H$3,Actuals!$B$2:$B$891,"US")+SUMIFS(Actuals!$F$2:$F$891,Actuals!$D$2:$D$891,$A21,Actuals!$A$2:$A$891,H$3,Actuals!$B$2:$B$891,"EU")*FX_EUR_USD -> 82574 | I21: =SUMIFS(Budget!$F$2:$F$1300,Budget!$A$2:$A$1300,I$3,Budget!$D$2:$D$1300,$A21) -> 102643 | J21: =SUMIFS(Actuals!$F$2:$F$891,Actuals!$D$2:$D$891,$A21,Actuals!$B$2:$B$891,"US")+SUMIFS(Actuals!$F$2:$F$891,Actuals!$D$2:$D$891,$A21,Actuals!$B$2:$B$891,"EU")*FX_EUR_USD -> 872844.88 | K21: =SUMIFS(Budget!$F$2:$F$1300,Budget!$A$2:$A$1300,"<="&K$3,Budget!$D$2:$D$1300,$A21) -> 889574 | L21: =J21-K21 -> -16729.12 | M21: =IFERROR(L21/K21,0) -> -0.018805765
A22: 6600 | B22: =VLOOKUP($A22,COA!$A$2:$E$30,2,FALSE) -> Recruiting | C22: =VLOOKUP($A22,COA!$A$2:$E$30,3,FALSE) -> Opex | D22: =SUMIFS(Actuals!$F$2:$F$891,Actuals!$D$2:$D$891,$A22,Actuals!$A$2:$A$891,D$3,Actuals!$B$2:$B$891,"US")+SUMIFS(Actuals!$F$2:$F$891,Actuals!$D$2:$D$891,$A22,Actuals!$A$2:$A$891,D$3,Actuals!$B$2:$B$891,"EU")*FX_EUR_USD -> 66790.8 | E22: =SUMIFS(Budget!$F$2:$F$1300,Budget!$A$2:$A$1300,E$3,Budget!$D$2:$D$1300,$A22) -> 65684 | F22: =SUMIFS(Actuals!$F$2:$F$891,Actuals!$D$2:$D$891,$A22,Actuals!$A$2:$A$891,F$3,Actuals!$B$2:$B$891,"US")+SUMIFS(Actuals!$F$2:$F$891,Actuals!$D$2:$D$891,$A22,Actuals!$A$2:$A$891,F$3,Actuals!$B$2:$B$891,"EU")*FX_EUR_USD -> 66202 | G22: =SUMIFS(Budget!$F$2:$F$1300,Budget!$A$2:$A$1300,G$3,Budget!$D$2:$D$1300,$A22) -> 66303 | H22: =SUMIFS(Actuals!$F$2:$F$891,Actuals!$D$2:$D$891,$A22,Actuals!$A$2:$A$891,H$3,Actuals!$B$2:$B$891,"US")+SUMIFS(Actuals!$F$2:$F$891,Actuals!$D$2:$D$891,$A22,Actuals!$A$2:$A$891,H$3,Actuals!$B$2:$B$891,"EU")*FX_EUR_USD -> 50024 | I22: =SUMIFS(Budget!$F$2:$F$1300,Budget!$A$2:$A$1300,I$3,Budget!$D$2:$D$1300,$A22) -> 66923 | J22: =SUMIFS(Actuals!$F$2:$F$891,Actuals!$D$2:$D$891,$A22,Actuals!$B$2:$B$891,"US")+SUMIFS(Actuals!$F$2:$F$891,Actuals!$D$2:$D$891,$A22,Actuals!$B$2:$B$891,"EU")*FX_EUR_USD -> 568305.16 | K22: =SUMIFS(Budget!$F$2:$F$1300,Budget!$A$2:$A$1300,"<="&K$3,Budget!$D$2:$D$1300,$A22) -> 579995 | L22: =J22-K22 -> -11689.84 | M22: =IFERROR(L22/K22,0) -> -0.02015507
A23: 6700 | B23: =VLOOKUP($A23,COA!$A$2:$E$30,2,FALSE) -> Contractors | C23: =VLOOKUP($A23,COA!$A$2:$E$30,3,FALSE) -> Opex | D23: =SUMIFS(Actuals!$F$2:$F$891,Actuals!$D$2:$D$891,$A23,Actuals!$A$2:$A$891,D$3,Actuals!$B$2:$B$891,"US")+SUMIFS(Actuals!$F$2:$F$891,Actuals!$D$2:$D$891,$A23,Actuals!$A$2:$A$891,D$3,Actuals!$B$2:$B$891,"EU")*FX_EUR_USD -> 128004.56 | E23: =SUMIFS(Budget!$F$2:$F$1300,Budget!$A$2:$A$1300,E$3,Budget!$D$2:$D$1300,$A23) -> 126500 | F23: =SUMIFS(Actuals!$F$2:$F$891,Actuals!$D$2:$D$891,$A23,Actuals!$A$2:$A$891,F$3,Actuals!$B$2:$B$891,"US")+SUMIFS(Actuals!$F$2:$F$891,Actuals!$D$2:$D$891,$A23,Actuals!$A$2:$A$891,F$3,Actuals!$B$2:$B$891,"EU")*FX_EUR_USD -> 125988 | G23: =SUMIFS(Budget!$F$2:$F$1300,Budget!$A$2:$A$1300,G$3,Budget!$D$2:$D$1300,$A23) -> 127694 | H23: =SUMIFS(Actuals!$F$2:$F$891,Actuals!$D$2:$D$891,$A23,Actuals!$A$2:$A$891,H$3,Actuals!$B$2:$B$891,"US")+SUMIFS(Actuals!$F$2:$F$891,Actuals!$D$2:$D$891,$A23,Actuals!$A$2:$A$891,H$3,Actuals!$B$2:$B$891,"EU")*FX_EUR_USD -> 99105 | I23: =SUMIFS(Budget!$F$2:$F$1300,Budget!$A$2:$A$1300,I$3,Budget!$D$2:$D$1300,$A23) -> 128887 | J23: =SUMIFS(Actuals!$F$2:$F$891,Actuals!$D$2:$D$891,$A23,Actuals!$B$2:$B$891,"US")+SUMIFS(Actuals!$F$2:$F$891,Actuals!$D$2:$D$891,$A23,Actuals!$B$2:$B$891,"EU")*FX_EUR_USD -> 1089732.8 | K23: =SUMIFS(Budget!$F$2:$F$1300,Budget!$A$2:$A$1300,"<="&K$3,Budget!$D$2:$D$1300,$A23) -> 1117022 | L23: =J23-K23 -> -27289.24 | M23: =IFERROR(L23/K23,0) -> -0.024430351
A24: 6900 | B24: =VLOOKUP($A24,COA!$A$2:$E$30,2,FALSE) -> Other opex | C24: =VLOOKUP($A24,COA!$A$2:$E$30,3,FALSE) -> Opex | D24: =SUMIFS(Actuals!$F$2:$F$891,Actuals!$D$2:$D$891,$A24,Actuals!$A$2:$A$891,D$3,Actuals!$B$2:$B$891,"US")+SUMIFS(Actuals!$F$2:$F$891,Actuals!$D$2:$D$891,$A24,Actuals!$A$2:$A$891,D$3,Actuals!$B$2:$B$891,"EU")*FX_EUR_USD -> 44501.56 | E24: =SUMIFS(Budget!$F$2:$F$1300,Budget!$A$2:$A$1300,E$3,Budget!$D$2:$D$1300,$A24) -> 43788 | F24: =SUMIFS(Actuals!$F$2:$F$891,Actuals!$D$2:$D$891,$A24,Actuals!$A$2:$A$891,F$3,Actuals!$B$2:$B$891,"US")+SUMIFS(Actuals!$F$2:$F$891,Actuals!$D$2:$D$891,$A24,Actuals!$A$2:$A$891,F$3,Actuals!$B$2:$B$891,"EU")*FX_EUR_USD -> 44031.12 | G24: =SUMIFS(Budget!$F$2:$F$1300,Budget!$A$2:$A$1300,G$3,Budget!$D$2:$D$1300,$A24) -> 44203 | H24: =SUMIFS(Actuals!$F$2:$F$891,Actuals!$D$2:$D$891,$A24,Actuals!$A$2:$A$891,H$3,Actuals!$B$2:$B$891,"US")+SUMIFS(Actuals!$F$2:$F$891,Actuals!$D$2:$D$891,$A24,Actuals!$A$2:$A$891,H$3,Actuals!$B$2:$B$891,"EU")*FX_EUR_USD -> 32944 | I24: =SUMIFS(Budget!$F$2:$F$1300,Budget!$A$2:$A$1300,I$3,Budget!$D$2:$D$1300,$A24) -> 44614 | J24: =SUMIFS(Actuals!$F$2:$F$891,Actuals!$D$2:$D$891,$A24,Actuals!$B$2:$B$891,"US")+SUMIFS(Actuals!$F$2:$F$891,Actuals!$D$2:$D$891,$A24,Actuals!$B$2:$B$891,"EU")*FX_EUR_USD -> 377614.8 | K24: =SUMIFS(Budget!$F$2:$F$1300,Budget!$A$2:$A$1300,"<="&K$3,Budget!$D$2:$D$1300,$A24) -> 386662 | L24: =J24-K24 -> -9047.2 | M24: =IFERROR(L24/K24,0) -> -0.023398213
B25: Total Opex | D25: =SUM(D13:D24) -> 4031273 | E25: =SUM(E13:E24) -> 4110833 | F25: =SUM(F13:F24) -> 4032498.8 | G25: =SUM(G13:G24) -> 4149617 | H25: =SUM(H13:H24) -> 3253761.8 | I25: =SUM(I13:I24) -> 4188395 | J25: =SUM(J13:J24) -> 35472415 | K25: =SUM(K13:K24) -> 36299436 | L25: =SUM(L13:L24) -> -827020.56 | M25: =IFERROR(L25/K25,0) -> -0.02278329
B26: EBITDA | D26: =D11-D25 -> -450522.88 | E26: =E11-E25 -> -604148 | F26: =F11-F25 -> -380022.8 | G26: =G11-G25 -> -563908 | H26: =H11-H25 -> 729587.24 | I26: =I11-I25 -> -521922 | J26: =J11-J25 -> -4089369.2 | K26: =K11-K25 -> -6066783 | L26: =L11-L25 -> 1977413.8 | M26: =IFERROR(L26/K26,0) -> -0.32594107
B27: EBITDA margin % | D27: =IFERROR(D26/D7,0) -> -0.10216532 | E27: =IFERROR(E26/E7,0) -> -0.13894487 | F27: =IFERROR(F26/F7,0) -> -0.083920839 | G27: =IFERROR(G26/G7,0) -> -0.12714734 | H27: =IFERROR(H26/H7,0) -> 0.1585487 | I27: =IFERROR(I26/I7,0) -> -0.11537306 | J27: =IFERROR(J26/J7,0) -> -0.10610831 | K27: =IFERROR(K26/K7,0) -> -0.16108234 | L27: =J27-K27 -> 0.054974029
A30: Headcount snapshot (pasted from Headcount Plan, HC Summary, 2026-10-02)
A31: Department | B31: Sep-26 HC | C31: Budget HC | D31: Variance
A32: Sales | B32: 21 | C32: 22 | D32: =B32-C32 -> -1
A33: Marketing | B33: 12 | C33: 13 | D33: =B33-C33 -> -1
A34: Customer Success | B34: 16 | C34: 16 | D34: =B34-C34 -> 0
A35: R&D | B35: 45 | C35: 51 | D35: =B35-C35 -> -6
A36: Product | B36: 8 | C36: 9 | D36: =B36-C36 -> -1
A37: G&A | B37: 10 | C37: 10 | D37: =B37-C37 -> 0
A38: Total | B38: =SUM(B32:B37) -> 112 | C38: =SUM(C32:C37) -> 121 | D38: =SUM(D32:D37) -> -9
A41: Notes
A42: 1. Variance = Actual - Budget. For expense lines a negative variance is favourable.
A43: 2. EU entity amounts are converted at the budget rate (Assumptions). Treasury reports actual-rate figures separately.
A44: 3. Q4 budget columns use reforecast RF2 (Budget tab, Version column).
...

Sheet Dept Variance
A1: Dept code | B1: Department | C1: Owner | D1: YTD Actual | E1: YTD Budget | F1: Variance | G1: Var % | H1: Flag | I1: Commentary
A2: SAL | B2: =VLOOKUP($A2,Departments!$A$2:$E$8,2,FALSE) -> Sales | C2: =VLOOKUP($A2,Departments!$A$2:$E$8,4,FALSE) -> Priya Natarajan | D2: =SUMIFS(Actuals!$F$2:$F$891,Actuals!$C$2:$C$891,$A2,Actuals!$B$2:$B$891,"US")+SUMIFS(Actuals!$F$2:$F$891,Actuals!$C$2:$C$891,$A2,Actuals!$B$2:$B$891,"EU")*FX_EUR_USD -> 7642983.8 | E2: =SUMIFS(Budget!$F$2:$F$1300,Budget!$C$2:$C$1300,$A2,Budget!$A$2:$A$1300,"<="&DATE(2026,9,1)) -> 7755975 | F2: =D2-E2 -> -112991.16 | G2: =IFERROR(F2/E2,0) -> -0.014568273 | H2: =IF(ABS(G2)>0.05,"Review","") | I2: Commissions above plan on 6% ARR over-attainment; T&E over by $62K for the EMEA field kickoff.
A3: MKT | B3: =VLOOKUP($A3,Departments!$A$2:$E$8,2,FALSE) -> Marketing | C3: =VLOOKUP($A3,Departments!$A$2:$E$8,4,FALSE) -> Luis Ortega | D3: =SUMIFS(Actuals!$F$2:$F$891,Actuals!$C$2:$C$891,$A3,Actuals!$B$2:$B$891,"US")+SUMIFS(Actuals!$F$2:$F$891,Actuals!$C$2:$C$891,$A3,Actuals!$B$2:$B$891,"EU")*FX_EUR_USD -> 5754705.8 | E3: =SUMIFS(Budget!$F$2:$F$1300,Budget!$C$2:$C$1300,$A3,Budget!$A$2:$A$1300,"<="&DATE(2026,9,1)) -> 5420844 | F3: =D3-E3 -> 333861.76 | G3: =IFERROR(F3/E3,0) -> 0.06158852 | H3: =IF(ABS(G3)>0.05,"Review","") -> Review | I3: Q2 programs over budget by about $410K: Series B launch events pulled forward from Q3, approved by CMO 2026-05-12. Expect Q3 and Q4 under budget.
A4: CS | B4: =VLOOKUP($A4,Departments!$A$2:$E$8,2,FALSE) -> Customer Success | C4: =VLOOKUP($A4,Departments!$A$2:$E$8,4,FALSE) -> Hannah Weiss | D4: =SUMIFS(Actuals!$F$2:$F$891,Actuals!$C$2:$C$891,$A4,Actuals!$B$2:$B$891,"US")+SUMIFS(Actuals!$F$2:$F$891,Actuals!$C$2:$C$891,$A4,Actuals!$B$2:$B$891,"EU")*FX_EUR_USD -> 3868600.4 | E4: =SUMIFS(Budget!$F$2:$F$1300,Budget!$C$2:$C$1300,$A4,Budget!$A$2:$A$1300,"<="&DATE(2026,9,1)) -> 4016985 | F4: =D4-E4 -> -148384.6 | G4: =IFERROR(F4/E4,0) -> -0.036939297 | H4: =IF(ABS(G4)>0.05,"Review","") | I4: On plan. Services delivery cost (5020) tracked in R&D hosting review, not here.
A5: RND | B5: =VLOOKUP($A5,Departments!$A$2:$E$8,2,FALSE) -> R&D | C5: =VLOOKUP($A5,Departments!$A$2:$E$8,4,FALSE) -> Wei Zhang | D5: =SUMIFS(Actuals!$F$2:$F$891,Actuals!$C$2:$C$891,$A5,Actuals!$B$2:$B$891,"US")+SUMIFS(Actuals!$F$2:$F$891,Actuals!$C$2:$C$891,$A5,Actuals!$B$2:$B$891,"EU")*FX_EUR_USD -> 16442874 | E5: =SUMIFS(Budget!$F$2:$F$1300,Budget!$C$2:$C$1300,$A5,Budget!$A$2:$A$1300,"<="&DATE(2026,9,1)) -> 17346700 | F5: =D5-E5 -> -903826 | G5: =IFERROR(F5/E5,0) -> -0.052103628 | H5: =IF(ABS(G5)>0.05,"Review","") -> Review | I5: Under budget on salaries, benefits and bonus from July: six requisitions slipped to Q4 (see Headcount Plan, Hiring Plan tab, status 'Slipped to Q4'). Hosting (5000) tracks usage, on plan.
A6: PRD | B6: =VLOOKUP($A6,Departments!$A$2:$E$8,2,FALSE) -> Product | C6: =VLOOKUP($A6,Departments!$A$2:$E$8,4,FALSE) -> Aisha Bello | D6: =SUMIFS(Actuals!$F$2:$F$891,Actuals!$C$2:$C$891,$A6,Actuals!$B$2:$B$891,"US")+SUMIFS(Actuals!$F$2:$F$891,Actuals!$C$2:$C$891,$A6,Actuals!$B$2:$B$891,"EU")*FX_EUR_USD -> 2523893 | E6: =SUMIFS(Budget!$F$2:$F$1300,Budget!$C$2:$C$1300,$A6,Budget!$A$2:$A$1300,"<="&DATE(2026,9,1)) -> 2600490 | F6: =D6-E6 -> -76597.04 | G6: =IFERROR(F6/E6,0) -> -0.029454849 | H6: =IF(ABS(G6)>0.05,"Review","") | I6: On plan.
A7: GA | B7: =VLOOKUP($A7,Departments!$A$2:$E$8,2,FALSE) -> G&A | C7: =VLOOKUP($A7,Departments!$A$2:$E$8,4,FALSE) -> Tom Hadley | D7: =SUMIFS(Actuals!$F$2:$F$891,Actuals!$C$2:$C$891,$A7,Actuals!$B$2:$B$891,"US")+SUMIFS(Actuals!$F$2:$F$891,Actuals!$C$2:$C$891,$A7,Actuals!$B$2:$B$891,"EU")*FX_EUR_USD -> 6395888.8 | E7: =SUMIFS(Budget!$F$2:$F$1300,Budget!$C$2:$C$1300,$A7,Budget!$A$2:$A$1300,"<="&DATE(2026,9,1)) -> 6588410 | F7: =D7-E7 -> -192521.2 | G7: =IFERROR(F7/E7,0) -> -0.029221193 | H7: =IF(ABS(G7)>0.05,"Review","") | I7: Professional fees over by $48K: audit readiness project (Deloitte SOW 2026-03).
A8: Total | D8: =SUM(D2:D7) -> 42628946 | E8: =SUM(E2:E7) -> 43729404 | F8: =SUM(F2:F7) -> -1100458.2 | G8: =IFERROR(F8/E8,0) -> -0.025165178

Sheet Commentary
A1: Period | B1: Department | C1: Author | D1: Commentary
A2: 46266 | B2: FP&A | C2: Maya Chen | D2: September close: revenue 3% over plan on Analytics upsell; EBITDA margin 2 points above plan mostly from R&D hiring slip, which is timing, not savings.
A3: 46266 | B3: RND | C3: Wei Zhang | D3: Six reqs (REQ-0412 to REQ-0417) slipped to Q4; offers out for two. Salary underspend will reverse in Q1 FY27 when the cohort starts.
A4: 46266 | B4: MKT | C4: Luis Ortega | D4: Q3 programs 18% under budget to offset the Q2 launch pull-forward. Full-year marketing programs expected on plan.
A5: 46235 | B5: FP&A | C5: Maya Chen | D5: Benefits load changed to 22% in July. Headcount Plan was updated by copying the value; it is not linked. Q4 rows there use 25% per People Ops guidance, which has not been approved by Finance.
A6: 46235 | B6: GA | C6: Tom Hadley | D6: Audit readiness SOW runs through November. $48K over plan YTD, expected $90K over by year end.
A7: 46204 | B7: SAL | C7: Priya Natarajan | D7: EMEA field kickoff in Lisbon drove T&E over plan. Commissions follow bookings; over-attainment is good news.
A8: 46204 | B8: FP&A | C8: Maya Chen | D8: Board KPI pack reports gross margin on the investor definition (includes Customer Success cost). BvA gross margin excludes it. Reconcile both before the October board meeting.
A9: 46174 | B9: FP&A | C9: Maya Chen | D9: Q4 reforecast RF2 loaded to the Budget tab. Board version kept for Jan to Sep. Versions are distinguished only by the Version column.
A10: 46174 | B10: CS | C10: Hannah Weiss | D10: Services delivery cost moved under COGS 5020 in June (was Opex 6700 for the CS team). Prior months restated in the GL, not in older BvA versions.
A11: 46143 | B11: MKT | C11: Luis Ortega | D11: Series B launch events pulled into May and June. CMO approval 2026-05-12 attached to the spend request.
A12: 46113 | B12: FP&A | C12: Maya Chen | D12: Revenue in this file is GAAP recognised revenue from the GL. The Board KPI pack shows ARR divided by 12 as run-rate revenue. They will never tie; do not try to reconcile them to the dollar.
A13: 46082 | B13: GA | C13: Tom Hadley | D13: FX: Treasury asked FP&A to keep the budget rate (1.08) for variance reporting. Actual-rate P&L is in the Treasury monthly file.
... A15: 46023 | B15: FP&A | C15: Maya Chen | D15: FY26 budget approved by the board on 2025-12-16. This file is the single source for monthly budget vs actuals.
